Workbook
Name _pn100: #REF!
Name _pn100: #REF!
Name _pn100: #REF!
Name _pn100: #REF!
Name _pn100: #REF!
Name _pn100: #REF!
Name _pn100: #REF!
Name _pn100: #REF!
Name _pn100: #REF!
Name _pn100: #REF!
Name _pn100: #REF!
Name _pn100: #REF!
Name _pn100: #REF!
Name _pn100: #REF!
Name _pn25: #REF!
Name _pn25: #REF!
Name _pn25: #REF!
Name _pn25: #REF!
Name _pn25: #REF!
Name _pn25: #REF!
Name _pn25: #REF!
Name _pn25: #REF!
Name _pn25: #REF!
Name _pn25: #REF!
Name _pn25: #REF!
Name _pn25: #REF!
Name _pn25: #REF!
Name _pn25: #REF!
Name distalavg: #REF!
Name distalavg: #REF!
Name distalavg: #REF!
Name distalavg: #REF!
Name distalavg: #REF!
Name distalavg: #REF!
Name distalavg: #REF!
Name distalavg: #REF!
Name distalavg: #REF!
Name distalavg: #REF!
Name distalavg: #REF!
Name distalavg: #REF!
Name distalavg: #REF!
Name distalavg: #REF!
Name distalavg100: #REF!
Name distalavgCA: #REF!
Name distalavgCA: #REF!
Name distalavgCA: #REF!
Name distalavgCA: #REF!
Name distalavgCA: #REF!
Name distalavgCA: #REF!
Name distalavgCA: #REF!
Name distalavgCA: #REF!
Name distalavgCA: #REF!
Name distalavgCA: #REF!
Name distalavgCA: #REF!
Name distalavgCA: #REF!
Name distalavgCA: #REF!
Name distalavgCA: #REF!
Name distalfailactual: #REF!
Name distalfailactual: #REF!
Name distalfailactual: #REF!

Sheet Worksheet Instructions
A1: Worksheet Instruction
A2: Intended Use
B3: This document is used as a worksheet for D9050 Cartridge Seal Integrity Vacuum Test Procedure to record the seal integrity data for reagent-on-board cartridges.
A4: Description
B5: Operator fills in cartridge ID, initial and final weight values in cells H3:J44.
B6: Formula in cells K3:K44 calculate the weight difference if there is a final weight. There is conditional formatting in these cells to turn the text body red if the weight loss exceeds the limit of 15 mg.
B7: Formula in cells L3:L44 indicate PASS/FAIL for appropriate conditions. Lack of data causes this cell to be blank. Conditional formatting is used to turn this text bold green or red for PASS and FAIL respectively.
B8: Operator selects Observation for STF characterization from the drop-down list if a sample fails for weight loss.
B9: For Production Order (PO) with multiple batches, enter all batch numbers on the worksheet.
A10: Naming Instructions
A11: Cepheid US Sites: | B11: Sample Naming as follows: Bag#_Sample/Replacement_Sample#Lid Laser Cut Pattern (for example 1_S_01+ OR 2_R_05X) unless otherwise specified per D12547 BOM.
B12: Sample Type for Xpert® Check should be entered as Sample/Replacement (for example 1_S_01+ or 2_R_05X)
A13: Solna: | B13: Sample Naming as follows: Bag#_Sample Type_Sample# (for example 1_1_01 OR 2_0_05) unless otherwise specified per D12547 BOM.
B14: Sample Type for XpertCheck should be entered as Zero (for example 1_0_01 or 2_0_05)
A15: Assay List | D15: ROBAL | G15: (Characterization) Observation
B16: Breast Cancer | E16: ROBAL-001 | H16: Broken Chimney
B17: BCR-ABL | E17: ROBAL-002 | H17: Film Seal (Leak)
B18: Bladder Cancer | E18: ROBAL-003 | H18: Lid Weld (Leak)
B19: Carba-R | E19: ROBAL-004 | H19: Unknown Leakage
B20: C. Diff | E20: ROBAL-005 | H20: Lid Outer Wall Blowout
B21: CTNG and Xpress CT/NG | E21: ROBAL-006 | H21: Other Damage
B22: Ebola | E22: ROBAL-007
B23: FIIFV/Hemosil | E23: ROBAL-008
B24: FlexCart-01 | E24: ROBAL-009
B25: FlexCart-02 | E25: ROBAL-010
B26: FlexCart-05 | E26: ROBAL-011
B27: Flu | E27: ROBAL-012
B28: GBS | E28: ROBAL-013
B29: HBV | E29: ROBAL-014
B30: HCV | E30: ROBAL-015
B31: HIV | E31: Jidoka-001
B32: HPV | E32: Jidoka-002
B33: Monkeypox | E33: NJB ROBAL 001
... B45: TV | E45: NJ-PL12
B46: Xpert Xpress MVP
B47: Xpert NPM1 Mutation
B48: LCE009 Xpress SARS-CoV-2 plus
B49: Van A
B50: Xpert Check
B51: Xpert Respiratory Panel
...

Sheet Datasheet (1)
B1: Part Number | D1: Batch Number(s) | F1: ROBAL | H1: Cartridge ID | I1: Initial Weight (mg) | J1: Final Weight (mg) | K1: Weight Loss (mg) | L1: Weight Loss Pass/Fail | M1: Observation
K3: =IF(J3<>"",I3-J3,"") | L3: =IF(J3="","",IF($F$10="","",IF(K3<=$F$10,"PASS","FAIL"))) | M3: =IF(L3="PASS","NA","")
B5: Cartridge Number (LSP) | D5: NOTE - All weight measurements should be done in "mg" and recorded in "mg". | K5: =IF(J5<>"",I5-J5,"") | L5: =IF(J5="","",IF($F$10="","",IF(K5<=$F$10,"PASS","FAIL"))) | M5: =IF(L5="PASS","NA","")
K7: =IF(J7<>"",I7-J7,"") | L7: =IF(J7="","",IF($F$10="","",IF(K7<=$F$10,"PASS","FAIL"))) | M7: =IF(L7="PASS","NA","")
B9: PO Number | D9: Assay Family | F9: Weight Loss Spec | K9: =IF(J9<>"",I9-J9,"") | L9: =IF(J9="","",IF($F$10="","",IF(K9<=$F$10,"PASS","FAIL"))) | M9: =IF(L9="PASS","NA","")
F10: =IF(OR(D10= "HBV", D10="HCV", D10="HIV", D10="Xpert E-RP"), 15, IF(OR(D10="Norovirus", D10="Strep A", D10="TV", D10="CTNG and Xpress CT/NG", D10="FlexCart-01", D10="FlexCart-05", D10="Flu", D10="BCR-ABL",D10="Breast Cancer", D10="Bladder Cancer", D10="C. Diff", D10="Carba-R", D10="Ebola", D10="FIIFV/Hemosil", D10="FlexCart-02", D10="GBS", D10="HPV", D10="MRSA", D10="MTB", D10="PA", D10="SA Comp", D10="SARS CoV2", D10="Xpress CoV-2 plus",D10="SARS CoV2 Flu/RSV",D10="SARS CoV2 Flu/RSV XC", D10="Xpress CoV-2/Flu/RSV plus",D10="Van A", D10="Xpert Check", D10="Xpert Xpress MVP", D10="Xpert NPM1 Mutation", D10="Xpert Respiratory Panel", D10="Xpert GI Panel", D10="Monkeypox", D10="Xpert PML-RARA RUO", D10="LCE010 Xpress CoV-2/Flu/RSV plus"),100,""))
K11: =IF(J11<>"",I11-J11,"") | L11: =IF(J11="","",IF($F$10="","",IF(K11<=$F$10,"PASS","FAIL"))) | M11: =IF(L11="PASS","NA","")
B13: Balance ID Number | D13: Balance Cal Due Date | K13: =IF(J13<>"",I13-J13,"") | L13: =IF(J13="","",IF($F$10="","",IF(K13<=$F$10,"PASS","FAIL"))) | M13: =IF(L13="PASS","NA","")
K15: =IF(J15<>"",I15-J15,"") | L15: =IF(J15="","",IF($F$10="","",IF(K15<=$F$10,"PASS","FAIL"))) | M15: =IF(L15="PASS","NA","")
K17: =IF(J17<>"",I17-J17,"") | L17: =IF(J17="","",IF($F$10="","",IF(K17<=$F$10,"PASS","FAIL"))) | M17: =IF(L17="PASS","NA","")
B19: Vacuum Oven ID Number | D19: Vacuum Oven Cal Due Date | K19: =IF(J19<>"",I19-J19,"") | L19: =IF(J19="","",IF($F$10="","",IF(K19<=$F$10,"PASS","FAIL"))) | M19: =IF(L19="PASS","NA","")
K21: =IF(J21<>"",I21-J21,"") | L21: =IF(J21="","",IF($F$10="","",IF(K21<=$F$10,"PASS","FAIL"))) | M21: =IF(L21="PASS","NA","")
K23: =IF(J23<>"",I23-J23,"") | L23: =IF(J23="","",IF($F$10="","",IF(K23<=$F$10,"PASS","FAIL"))) | M23: =IF(L23="PASS","NA","")
B24: Timer ID Number | D24: Timer Cal Due Date
K25: =IF(J25<>"",I25-J25,"") | L25: =IF(J25="","",IF($F$10="","",IF(K25<=$F$10,"PASS","FAIL"))) | M25: =IF(L25="PASS","NA","")
K27: =IF(J27<>"",I27-J27,"") | L27: =IF(J27="","",IF($F$10="","",IF(K27<=$F$10,"PASS","FAIL"))) | M27: =IF(L27="PASS","NA","")
B29: Configuration of Cartridge Lid with Chamber Identification | K29: =IF(J29<>"",I29-J29,"") | L29: =IF(J29="","",IF($F$10="","",IF(K29<=$F$10,"PASS","FAIL"))) | M29: =IF(L29="PASS","NA","")
K31: =IF(J31<>"",I31-J31,"") | L31: =IF(J31="","",IF($F$10="","",IF(K31<=$F$10,"PASS","FAIL"))) | M31: =IF(L31="PASS","NA","")
K33: =IF(J33<>"",I33-J33,"") | L33: =IF(J33="","",IF($F$10="","",IF(K33<=$F$10,"PASS","FAIL"))) | M33: =IF(L33="PASS","NA","")
K35: =IF(J35<>"",I35-J35,"") | L35: =IF(J35="","",IF($F$10="","",IF(K35<=$F$10,"PASS","FAIL"))) | M35: =IF(L35="PASS","NA","")
K37: =IF(J37<>"",I37-J37,"") | L37: =IF(J37="","",IF($F$10="","",IF(K37<=$F$10,"PASS","FAIL"))) | M37: =IF(L37="PASS","NA","")
K39: =IF(J39<>"",I39-J39,"") | L39: =IF(J39="","",IF($F$10="","",IF(K39<=$F$10,"PASS","FAIL"))) | M39: =IF(L39="PASS","NA","")
K41: =IF(J41<>"",I41-J41,"") | L41: =IF(J41="","",IF($F$10="","",IF(K41<=$F$10,"PASS","FAIL"))) | M41: =IF(L41="PASS","NA","")
B42: Name of Tester
K43: =IF(J43<>"",I43-J43,"") | L43: =IF(J43="","",IF($F$10="","",IF(K43<=$F$10,"PASS","FAIL"))) | M43: =IF(L43="PASS","NA","")
K45: =IF(J45<>"",I45-J45,"") | L45: =IF(J45="","",IF($F$10="","",IF(K45<=$F$10,"PASS","FAIL"))) | M45: =IF(L45="PASS","NA","")
B46: Signature | D46: Date
K49: =IF(J49<>"",I49-J49,"") | L49: =IF(J49="","",IF($F$10="","",IF(K49<=$F$10,"PASS","FAIL")))
B50: Comments | K50: For Information Only
K51: OC Mold(s) | M51: Lid Mold(s)

Sheet Datasheet (2)
B1: Part Number | D1: Batch Number(s) | F1: ROBAL | H1: Cartridge ID | I1: Initial Weight (mg) | J1: Final Weight (mg) | K1: Weight Loss (mg) | L1: Weight Loss Pass/Fail | M1: Observation
B2: =IF('Datasheet (1)'!B2:C3="","",'Datasheet (1)'!B2:C3) | D2: =IF('Datasheet (1)'!D2:E3="","",'Datasheet (1)'!D2:E3) | F2: =IF('Datasheet (1)'!F2:F3="","",'Datasheet (1)'!F2:F3)
K3: =IF(J3<>"",I3-J3,"") | L3: =IF(J3="","",IF($F$10="","",IF(K3<=$F$10,"PASS","FAIL"))) | M3: =IF(L3="PASS","NA","" )
B5: Cartridge Number (LSP) | D5: NOTE - All weight measurements should be done in "mg" and recorded in "mg". | K5: =IF(J5<>"",I5-J5,"") | L5: =IF(J5="","",IF($F$10="","",IF(K5<=$F$10,"PASS","FAIL"))) | M5: =IF(L5="PASS","NA","")
B6: =IF('Datasheet (1)'!B6:C7="","",'Datasheet (1)'!B6:C7)
K7: =IF(J7<>"",I7-J7,"") | L7: =IF(J7="","",IF($F$10="","",IF(K7<=$F$10,"PASS","FAIL"))) | M7: =IF(L7="PASS","NA","")
B9: PO Number | D9: Assay Family | F9: Weight Loss Spec | K9: =IF(J9<>"",I9-J9,"") | L9: =IF(J9="","",IF($F$10="","",IF(K9<=$F$10,"PASS","FAIL"))) | M9: =IF(L9="PASS","NA","")
B10: =IF('Datasheet (1)'!B10:C11="","",'Datasheet (1)'!B10:C11) | D10: =IF('Datasheet (1)'!D10:E11="","",'Datasheet (1)'!D10:E11) | F10: =IF(OR(D10= "HBV", D10="HCV", D10="HIV", D10="Xpert E-RP"), 15, IF(OR(D10="Norovirus", D10="Strep A", D10="TV", D10="CTNG and Xpress CT/NG", D10="FlexCart-01", D10="FlexCart-05", D10="Flu", D10="BCR-ABL",D10="Breast Cancer", D10="Bladder Cancer", D10="C. Diff", D10="Carba-R", D10="Ebola", D10="FIIFV/Hemosil", D10="FlexCart-02", D10="GBS", D10="HPV", D10="MRSA", D10="MTB", D10="PA", D10="SA Comp", D10="SARS CoV2", D10="Xpress CoV-2 plus",D10="SARS CoV2 Flu/RSV",D10="SARS CoV2 Flu/RSV XC", D10="Xpress CoV-2/Flu/RSV plus",D10="Van A", D10="Xpert Check", D10="Xpert Xpress MVP", D10="Xpert NPM1 Mutation", D10="Xpert Respiratory Panel", D10="Xpert GI Panel", D10="Monkeypox", D10="Xpert PML-RARA RUO", D10="LCE010 Xpress CoV-2/Flu/RSV plus"),100,""))
K11: =IF(J11<>"",I11-J11,"") | L11: =IF(J11="","",IF($F$10="","",IF(K11<=$F$10,"PASS","FAIL"))) | M11: =IF(L11="PASS","NA","")
B13: Balance ID Number | D13: Balance Cal Due Date | K13: =IF(J13<>"",I13-J13,"") | L13: =IF(J13="","",IF($F$10="","",IF(K13<=$F$10,"PASS","FAIL"))) | M13: =IF(L13="PASS","NA","")
K15: =IF(J15<>"",I15-J15,"") | L15: =IF(J15="","",IF($F$10="","",IF(K15<=$F$10,"PASS","FAIL"))) | M15: =IF(L15="PASS","NA","")
K17: =IF(J17<>"",I17-J17,"") | L17: =IF(J17="","",IF($F$10="","",IF(K17<=$F$10,"PASS","FAIL"))) | M17: =IF(L17="PASS","NA","")
B19: Vacuum Oven ID Number | D19: Vacuum Oven Cal Due Date | K19: =IF(J19<>"",I19-J19,"") | L19: =IF(J19="","",IF($F$10="","",IF(K19<=$F$10,"PASS","FAIL"))) | M19: =IF(L19="PASS","NA","")
K21: =IF(J21<>"",I21-J21,"") | L21: =IF(J21="","",IF($F$10="","",IF(K21<=$F$10,"PASS","FAIL"))) | M21: =IF(L21="PASS","NA","")
K23: =IF(J23<>"",I23-J23,"") | L23: =IF(J23="","",IF($F$10="","",IF(K23<=$F$10,"PASS","FAIL"))) | M23: =IF(L23="PASS","NA","")
B24: Timer ID Number | D24: Timer Cal Due Date
K25: =IF(J25<>"",I25-J25,"") | L25: =IF(J25="","",IF($F$10="","",IF(K25<=$F$10,"PASS","FAIL"))) | M25: =IF(L25="PASS","NA","")
K27: =IF(J27<>"",I27-J27,"") | L27: =IF(J27="","",IF($F$10="","",IF(K27<=$F$10,"PASS","FAIL"))) | M27: =IF(L27="PASS","NA","")
B29: Configuration of Cartridge Lid with Chamber Identification | K29: =IF(J29<>"",I29-J29,"") | L29: =IF(J29="","",IF($F$10="","",IF(K29<=$F$10,"PASS","FAIL"))) | M29: =IF(L29="PASS","NA","")
K31: =IF(J31<>"",I31-J31,"") | L31: =IF(J31="","",IF($F$10="","",IF(K31<=$F$10,"PASS","FAIL"))) | M31: =IF(L31="PASS","NA","")
K33: =IF(J33<>"",I33-J33,"") | L33: =IF(J33="","",IF($F$10="","",IF(K33<=$F$10,"PASS","FAIL"))) | M33: =IF(L33="PASS","NA","")
K35: =IF(J35<>"",I35-J35,"") | L35: =IF(J35="","",IF($F$10="","",IF(K35<=$F$10,"PASS","FAIL"))) | M35: =IF(L35="PASS","NA","")
K37: =IF(J37<>"",I37-J37,"") | L37: =IF(J37="","",IF($F$10="","",IF(K37<=$F$10,"PASS","FAIL"))) | M37: =IF(L37="PASS","NA","")
K39: =IF(J39<>"",I39-J39,"") | L39: =IF(J39="","",IF($F$10="","",IF(K39<=$F$10,"PASS","FAIL"))) | M39: =IF(L39="PASS","NA","")
K41: =IF(J41<>"",I41-J41,"") | L41: =IF(J41="","",IF($F$10="","",IF(K41<=$F$10,"PASS","FAIL"))) | M41: =IF(L41="PASS","NA","")
B42: Name of Tester
K43: =IF(J43<>"",I43-J43,"") | L43: =IF(J43="","",IF($F$10="","",IF(K43<=$F$10,"PASS","FAIL"))) | M43: =IF(L43="PASS","NA","")
K45: =IF(J45<>"",I45-J45,"") | L45: =IF(J45="","",IF($F$10="","",IF(K45<=$F$10,"PASS","FAIL"))) | M45: =IF(L45="PASS","NA","")
B46: Signature | D46: Date
B50: Comments | K50: For Information Only
K51: OC Mold(s) | M51: Lid Mold(s)

Sheet Datasheet (3)
B1: Part Number | D1: Batch Number(s) | F1: ROBAL | H1: Cartridge ID | I1: Initial Weight (mg) | J1: Final Weight (mg) | K1: Weight Loss (mg) | L1: Weight Loss Pass/Fail | M1: Observation
B2: =IF('Datasheet (1)'!B2:C3="","",'Datasheet (1)'!B2:C3) | D2: =IF('Datasheet (1)'!D2:E3="","",'Datasheet (1)'!D2:E3) | F2: =IF('Datasheet (1)'!F2:F3="","",'Datasheet (1)'!F2:F3)
K3: =IF(J3<>"",I3-J3,"") | L3: =IF(J3="","",IF($F$10="","",IF(K3<=$F$10,"PASS","FAIL"))) | M3: =IF(L3="PASS","NA","" )
B5: Cartridge Number (LSP) | D5: NOTE - All weight measurements should be done in "mg" and recorded in "mg". | K5: =IF(J5<>"",I5-J5,"") | L5: =IF(J5="","",IF($F$10="","",IF(K5<=$F$10,"PASS","FAIL"))) | M5: =IF(L5="PASS","NA","")
B6: =IF('Datasheet (1)'!B6:C7="","",'Datasheet (1)'!B6:C7)
K7: =IF(J7<>"",I7-J7,"") | L7: =IF(J7="","",IF($F$10="","",IF(K7<=$F$10,"PASS","FAIL"))) | M7: =IF(L7="PASS","NA","")
B9: PO Number | D9: Assay Family | F9: Weight Loss Spec | K9: =IF(J9<>"",I9-J9,"") | L9: =IF(J9="","",IF($F$10="","",IF(K9<=$F$10,"PASS","FAIL"))) | M9: =IF(L9="PASS","NA","")
B10: =IF('Datasheet (1)'!B10:C11="","",'Datasheet (1)'!B10:C11) | D10: =IF('Datasheet (1)'!D10:E11="","",'Datasheet (1)'!D10:E11) | F10: =IF(OR(D10= "HBV", D10="HCV", D10="HIV", D10="Xpert E-RP"), 15, IF(OR(D10="Norovirus", D10="Strep A", D10="TV", D10="CTNG and Xpress CT/NG", D10="FlexCart-01", D10="FlexCart-05", D10="Flu", D10="BCR-ABL",D10="Breast Cancer", D10="Bladder Cancer", D10="C. Diff", D10="Carba-R", D10="Ebola", D10="FIIFV/Hemosil", D10="FlexCart-02", D10="GBS", D10="HPV", D10="MRSA", D10="MTB", D10="PA", D10="SA Comp", D10="SARS CoV2", D10="Xpress CoV-2 plus",D10="SARS CoV2 Flu/RSV",D10="SARS CoV2 Flu/RSV XC", D10="Xpress CoV-2/Flu/RSV plus",D10="Van A", D10="Xpert Check", D10="Xpert Xpress MVP", D10="Xpert NPM1 Mutation", D10="Xpert Respiratory Panel", D10="Xpert GI Panel", D10="Monkeypox", D10="Xpert PML-RARA RUO", D10="LCE010 Xpress CoV-2/Flu/RSV plus"),100,""))
K11: =IF(J11<>"",I11-J11,"") | L11: =IF(J11="","",IF($F$10="","",IF(K11<=$F$10,"PASS","FAIL"))) | M11: =IF(L11="PASS","NA","")
B13: Balance ID Number | D13: Balance Cal Due Date | K13: =IF(J13<>"",I13-J13,"") | L13: =IF(J13="","",IF($F$10="","",IF(K13<=$F$10,"PASS","FAIL"))) | M13: =IF(L13="PASS","NA","")
K15: =IF(J15<>"",I15-J15,"") | L15: =IF(J15="","",IF($F$10="","",IF(K15<=$F$10,"PASS","FAIL"))) | M15: =IF(L15="PASS","NA","")
K17: =IF(J17<>"",I17-J17,"") | L17: =IF(J17="","",IF($F$10="","",IF(K17<=$F$10,"PASS","FAIL"))) | M17: =IF(L17="PASS","NA","")
B19: Vacuum Oven ID Number | D19: Vacuum Oven Cal Due Date | K19: =IF(J19<>"",I19-J19,"") | L19: =IF(J19="","",IF($F$10="","",IF(K19<=$F$10,"PASS","FAIL"))) | M19: =IF(L19="PASS","NA","")
K21: =IF(J21<>"",I21-J21,"") | L21: =IF(J21="","",IF($F$10="","",IF(K21<=$F$10,"PASS","FAIL"))) | M21: =IF(L21="PASS","NA","")
K23: =IF(J23<>"",I23-J23,"") | L23: =IF(J23="","",IF($F$10="","",IF(K23<=$F$10,"PASS","FAIL"))) | M23: =IF(L23="PASS","NA","")
B24: Timer ID Number | D24: Timer Cal Due Date
K25: =IF(J25<>"",I25-J25,"") | L25: =IF(J25="","",IF($F$10="","",IF(K25<=$F$10,"PASS","FAIL"))) | M25: =IF(L25="PASS","NA","")
K27: =IF(J27<>"",I27-J27,"") | L27: =IF(J27="","",IF($F$10="","",IF(K27<=$F$10,"PASS","FAIL"))) | M27: =IF(L27="PASS","NA","")
B29: Configuration of Cartridge Lid with Chamber Identification | K29: =IF(J29<>"",I29-J29,"") | L29: =IF(J29="","",IF($F$10="","",IF(K29<=$F$10,"PASS","FAIL"))) | M29: =IF(L29="PASS","NA","")
K31: =IF(J31<>"",I31-J31,"") | L31: =IF(J31="","",IF($F$10="","",IF(K31<=$F$10,"PASS","FAIL"))) | M31: =IF(L31="PASS","NA","")
K33: =IF(J33<>"",I33-J33,"") | L33: =IF(J33="","",IF($F$10="","",IF(K33<=$F$10,"PASS","FAIL"))) | M33: =IF(L33="PASS","NA","")
K35: =IF(J35<>"",I35-J35,"") | L35: =IF(J35="","",IF($F$10="","",IF(K35<=$F$10,"PASS","FAIL"))) | M35: =IF(L35="PASS","NA","")
K37: =IF(J37<>"",I37-J37,"") | L37: =IF(J37="","",IF($F$10="","",IF(K37<=$F$10,"PASS","FAIL"))) | M37: =IF(L37="PASS","NA","")
K39: =IF(J39<>"",I39-J39,"") | L39: =IF(J39="","",IF($F$10="","",IF(K39<=$F$10,"PASS","FAIL"))) | M39: =IF(L39="PASS","NA","")
K41: =IF(J41<>"",I41-J41,"") | L41: =IF(J41="","",IF($F$10="","",IF(K41<=$F$10,"PASS","FAIL"))) | M41: =IF(L41="PASS","NA","")
B42: Name of Tester
K43: =IF(J43<>"",I43-J43,"") | L43: =IF(J43="","",IF($F$10="","",IF(K43<=$F$10,"PASS","FAIL"))) | M43: =IF(L43="PASS","NA","")
K45: =IF(J45<>"",I45-J45,"") | L45: =IF(J45="","",IF($F$10="","",IF(K45<=$F$10,"PASS","FAIL"))) | M45: =IF(L45="PASS","NA","")
B46: Signature | D46: Date
B50: Comments | K50: For Information Only
K51: OC Mold(s) | M51: Lid Mold(s)

Sheet Datasheet (4)
B1: Part Number | D1: Batch Number(s) | F1: ROBAL | H1: Cartridge ID | I1: Initial Weight (mg) | J1: Final Weight (mg) | K1: Weight Loss (mg) | L1: Weight Loss Pass/Fail | M1: Observation
B2: =IF('Datasheet (1)'!B2:C3="","",'Datasheet (1)'!B2:C3) | D2: =IF('Datasheet (1)'!D2:E3="","",'Datasheet (1)'!D2:E3) | F2: =IF('Datasheet (1)'!F2:F3="","",'Datasheet (1)'!F2:F3)
K3: =IF(J3<>"",I3-J3,"") | L3: =IF(J3="","",IF($F$10="","",IF(K3<=$F$10,"PASS","FAIL"))) | M3: =IF(L3="PASS","NA","" )
B5: Cartridge Number (LSP) | D5: NOTE - All weight measurements should be done in "mg" and recorded in "mg". | K5: =IF(J5<>"",I5-J5,"") | L5: =IF(J5="","",IF($F$10="","",IF(K5<=$F$10,"PASS","FAIL"))) | M5: =IF(L5="PASS","NA","")
B6: =IF('Datasheet (1)'!B6:C7="","",'Datasheet (1)'!B6:C7)
K7: =IF(J7<>"",I7-J7,"") | L7: =IF(J7="","",IF($F$10="","",IF(K7<=$F$10,"PASS","FAIL"))) | M7: =IF(L7="PASS","NA","")
B9: PO Number | D9: Assay Family | F9: Weight Loss Spec | K9: =IF(J9<>"",I9-J9,"") | L9: =IF(J9="","",IF($F$10="","",IF(K9<=$F$10,"PASS","FAIL"))) | M9: =IF(L9="PASS","NA","")
B10: =IF('Datasheet (1)'!B10:C11="","",'Datasheet (1)'!B10:C11) | D10: =IF('Datasheet (1)'!D10:E11="","",'Datasheet (1)'!D10:E11) | F10: =IF(OR(D10= "HBV", D10="HCV", D10="HIV", D10="Xpert E-RP"), 15, IF(OR(D10="Norovirus", D10="Strep A", D10="TV", D10="CTNG and Xpress CT/NG", D10="FlexCart-01", D10="FlexCart-05", D10="Flu", D10="BCR-ABL",D10="Breast Cancer", D10="Bladder Cancer", D10="C. Diff", D10="Carba-R", D10="Ebola", D10="FIIFV/Hemosil", D10="FlexCart-02", D10="GBS", D10="HPV", D10="MRSA", D10="MTB", D10="PA", D10="SA Comp", D10="SARS CoV2", D10="Xpress CoV-2 plus",D10="SARS CoV2 Flu/RSV",D10="SARS CoV2 Flu/RSV XC", D10="Xpress CoV-2/Flu/RSV plus",D10="Van A", D10="Xpert Check", D10="Xpert Xpress MVP", D10="Xpert NPM1 Mutation", D10="Xpert Respiratory Panel", D10="Xpert GI Panel", D10="Monkeypox", D10="Xpert PML-RARA RUO", D10="LCE010 Xpress CoV-2/Flu/RSV plus"),100,""))
K11: =IF(J11<>"",I11-J11,"") | L11: =IF(J11="","",IF($F$10="","",IF(K11<=$F$10,"PASS","FAIL"))) | M11: =IF(L11="PASS","NA","")
B13: Balance ID Number | D13: Balance Cal Due Date | K13: =IF(J13<>"",I13-J13,"") | L13: =IF(J13="","",IF($F$10="","",IF(K13<=$F$10,"PASS","FAIL"))) | M13: =IF(L13="PASS","NA","")
K15: =IF(J15<>"",I15-J15,"") | L15: =IF(J15="","",IF($F$10="","",IF(K15<=$F$10,"PASS","FAIL"))) | M15: =IF(L15="PASS","NA","")
K17: =IF(J17<>"",I17-J17,"") | L17: =IF(J17="","",IF($F$10="","",IF(K17<=$F$10,"PASS","FAIL"))) | M17: =IF(L17="PASS","NA","")
B19: Vacuum Oven ID Number | D19: Vacuum Oven Cal Due Date | K19: =IF(J19<>"",I19-J19,"") | L19: =IF(J19="","",IF($F$10="","",IF(K19<=$F$10,"PASS","FAIL"))) | M19: =IF(L19="PASS","NA","")
K21: =IF(J21<>"",I21-J21,"") | L21: =IF(J21="","",IF($F$10="","",IF(K21<=$F$10,"PASS","FAIL"))) | M21: =IF(L21="PASS","NA","")
K23: =IF(J23<>"",I23-J23,"") | L23: =IF(J23="","",IF($F$10="","",IF(K23<=$F$10,"PASS","FAIL"))) | M23: =IF(L23="PASS","NA","")
B24: Timer ID Number | D24: Timer Cal Due Date
K25: =IF(J25<>"",I25-J25,"") | L25: =IF(J25="","",IF($F$10="","",IF(K25<=$F$10,"PASS","FAIL"))) | M25: =IF(L25="PASS","NA","")
K27: =IF(J27<>"",I27-J27,"") | L27: =IF(J27="","",IF($F$10="","",IF(K27<=$F$10,"PASS","FAIL"))) | M27: =IF(L27="PASS","NA","")
B29: Configuration of Cartridge Lid with Chamber Identification | K29: =IF(J29<>"",I29-J29,"") | L29: =IF(J29="","",IF($F$10="","",IF(K29<=$F$10,"PASS","FAIL"))) | M29: =IF(L29="PASS","NA","")
K31: =IF(J31<>"",I31-J31,"") | L31: =IF(J31="","",IF($F$10="","",IF(K31<=$F$10,"PASS","FAIL"))) | M31: =IF(L31="PASS","NA","")
K33: =IF(J33<>"",I33-J33,"") | L33: =IF(J33="","",IF($F$10="","",IF(K33<=$F$10,"PASS","FAIL"))) | M33: =IF(L33="PASS","NA","")
K35: =IF(J35<>"",I35-J35,"") | L35: =IF(J35="","",IF($F$10="","",IF(K35<=$F$10,"PASS","FAIL"))) | M35: =IF(L35="PASS","NA","")
K37: =IF(J37<>"",I37-J37,"") | L37: =IF(J37="","",IF($F$10="","",IF(K37<=$F$10,"PASS","FAIL"))) | M37: =IF(L37="PASS","NA","")
K39: =IF(J39<>"",I39-J39,"") | L39: =IF(J39="","",IF($F$10="","",IF(K39<=$F$10,"PASS","FAIL"))) | M39: =IF(L39="PASS","NA","")
K41: =IF(J41<>"",I41-J41,"") | L41: =IF(J41="","",IF($F$10="","",IF(K41<=$F$10,"PASS","FAIL"))) | M41: =IF(L41="PASS","NA","")
B42: Name of Tester
K43: =IF(J43<>"",I43-J43,"") | L43: =IF(J43="","",IF($F$10="","",IF(K43<=$F$10,"PASS","FAIL"))) | M43: =IF(L43="PASS","NA","")
K45: =IF(J45<>"",I45-J45,"") | L45: =IF(J45="","",IF($F$10="","",IF(K45<=$F$10,"PASS","FAIL"))) | M45: =IF(L45="PASS","NA","")
B46: Signature | D46: Date
B50: Comments | K50: For Information Only
K51: OC Mold(s) | M51: Lid Mold(s)

Sheet Datasheet (5)
B1: Part Number | D1: Batch Number(s) | F1: ROBAL | H1: Cartridge ID | I1: Initial Weight (mg) | J1: Final Weight (mg) | K1: Weight Loss (mg) | L1: Weight Loss Pass/Fail | M1: Observation
B2: =IF('Datasheet (1)'!B2:C3="","",'Datasheet (1)'!B2:C3) | D2: =IF('Datasheet (1)'!D2:E3="","",'Datasheet (1)'!D2:E3) | F2: =IF('Datasheet (1)'!F2:F3="","",'Datasheet (1)'!F2:F3)
K3: =IF(J3<>"",I3-J3,"") | L3: =IF(J3="","",IF($F$10="","",IF(K3<=$F$10,"PASS","FAIL"))) | M3: =IF(L3="PASS","NA","" )
B5: Cartridge Number (LSP) | D5: NOTE - All weight measurements should be done in "mg" and recorded in "mg". | K5: =IF(J5<>"",I5-J5,"") | L5: =IF(J5="","",IF($F$10="","",IF(K5<=$F$10,"PASS","FAIL"))) | M5: =IF(L5="PASS","NA","")
B6: =IF('Datasheet (1)'!B6:C7="","",'Datasheet (1)'!B6:C7)
K7: =IF(J7<>"",I7-J7,"") | L7: =IF(J7="","",IF($F$10="","",IF(K7<=$F$10,"PASS","FAIL"))) | M7: =IF(L7="PASS","NA","")
B9: PO Number | D9: Assay Family | F9: Weight Loss Spec | K9: =IF(J9<>"",I9-J9,"") | L9: =IF(J9="","",IF($F$10="","",IF(K9<=$F$10,"PASS","FAIL"))) | M9: =IF(L9="PASS","NA","")
B10: =IF('Datasheet (1)'!B10:C11="","",'Datasheet (1)'!B10:C11) | D10: =IF('Datasheet (1)'!D10:E11="","",'Datasheet (1)'!D10:E11) | F10: =IF(OR(D10= "HBV", D10="HCV", D10="HIV", D10="Xpert E-RP"), 15, IF(OR(D10="Norovirus", D10="Strep A", D10="TV", D10="CTNG and Xpress CT/NG", D10="FlexCart-01", D10="FlexCart-05", D10="Flu", D10="BCR-ABL",D10="Breast Cancer", D10="Bladder Cancer", D10="C. Diff", D10="Carba-R", D10="Ebola", D10="FIIFV/Hemosil", D10="FlexCart-02", D10="GBS", D10="HPV", D10="MRSA", D10="MTB", D10="PA", D10="SA Comp", D10="SARS CoV2", D10="Xpress CoV-2 plus",D10="SARS CoV2 Flu/RSV",D10="SARS CoV2 Flu/RSV XC", D10="Xpress CoV-2/Flu/RSV plus",D10="Van A", D10="Xpert Check", D10="Xpert Xpress MVP", D10="Xpert NPM1 Mutation", D10="Xpert Respiratory Panel", D10="Xpert GI Panel", D10="Monkeypox", D10="Xpert PML-RARA RUO", D10="LCE010 Xpress CoV-2/Flu/RSV plus"),100,""))
K11: =IF(J11<>"",I11-J11,"") | L11: =IF(J11="","",IF($F$10="","",IF(K11<=$F$10,"PASS","FAIL"))) | M11: =IF(L11="PASS","NA","")
B13: Balance ID Number | D13: Balance Cal Due Date | K13: =IF(J13<>"",I13-J13,"") | L13: =IF(J13="","",IF($F$10="","",IF(K13<=$F$10,"PASS","FAIL"))) | M13: =IF(L13="PASS","NA","")
K15: =IF(J15<>"",I15-J15,"") | L15: =IF(J15="","",IF($F$10="","",IF(K15<=$F$10,"PASS","FAIL"))) | M15: =IF(L15="PASS","NA","")
K17: =IF(J17<>"",I17-J17,"") | L17: =IF(J17="","",IF($F$10="","",IF(K17<=$F$10,"PASS","FAIL"))) | M17: =IF(L17="PASS","NA","")
B19: Vacuum Oven ID Number | D19: Vacuum Oven Cal Due Date | K19: =IF(J19<>"",I19-J19,"") | L19: =IF(J19="","",IF($F$10="","",IF(K19<=$F$10,"PASS","FAIL"))) | M19: =IF(L19="PASS","NA","")
K21: =IF(J21<>"",I21-J21,"") | L21: =IF(J21="","",IF($F$10="","",IF(K21<=$F$10,"PASS","FAIL"))) | M21: =IF(L21="PASS","NA","")
K23: =IF(J23<>"",I23-J23,"") | L23: =IF(J23="","",IF($F$10="","",IF(K23<=$F$10,"PASS","FAIL"))) | M23: =IF(L23="PASS","NA","")
B24: Timer ID Number | D24: Timer Cal Due Date
K25: =IF(J25<>"",I25-J25,"") | L25: =IF(J25="","",IF($F$10="","",IF(K25<=$F$10,"PASS","FAIL"))) | M25: =IF(L25="PASS","NA","")
K27: =IF(J27<>"",I27-J27,"") | L27: =IF(J27="","",IF($F$10="","",IF(K27<=$F$10,"PASS","FAIL"))) | M27: =IF(L27="PASS","NA","")
B29: Configuration of Cartridge Lid with Chamber Identification | K29: =IF(J29<>"",I29-J29,"") | L29: =IF(J29="","",IF($F$10="","",IF(K29<=$F$10,"PASS","FAIL"))) | M29: =IF(L29="PASS","NA","")
K31: =IF(J31<>"",I31-J31,"") | L31: =IF(J31="","",IF($F$10="","",IF(K31<=$F$10,"PASS","FAIL"))) | M31: =IF(L31="PASS","NA","")
K33: =IF(J33<>"",I33-J33,"") | L33: =IF(J33="","",IF($F$10="","",IF(K33<=$F$10,"PASS","FAIL"))) | M33: =IF(L33="PASS","NA","")
K35: =IF(J35<>"",I35-J35,"") | L35: =IF(J35="","",IF($F$10="","",IF(K35<=$F$10,"PASS","FAIL"))) | M35: =IF(L35="PASS","NA","")
K37: =IF(J37<>"",I37-J37,"") | L37: =IF(J37="","",IF($F$10="","",IF(K37<=$F$10,"PASS","FAIL"))) | M37: =IF(L37="PASS","NA","")
K39: =IF(J39<>"",I39-J39,"") | L39: =IF(J39="","",IF($F$10="","",IF(K39<=$F$10,"PASS","FAIL"))) | M39: =IF(L39="PASS","NA","")
K41: =IF(J41<>"",I41-J41,"") | L41: =IF(J41="","",IF($F$10="","",IF(K41<=$F$10,"PASS","FAIL"))) | M41: =IF(L41="PASS","NA","")
B42: Name of Tester
K43: =IF(J43<>"",I43-J43,"") | L43: =IF(J43="","",IF($F$10="","",IF(K43<=$F$10,"PASS","FAIL"))) | M43: =IF(L43="PASS","NA","")
K45: =IF(J45<>"",I45-J45,"") | L45: =IF(J45="","",IF($F$10="","",IF(K45<=$F$10,"PASS","FAIL"))) | M45: =IF(L45="PASS","NA","")
B46: Signature | D46: Date
B50: Comments | K50: For Information Only
K51: OC Mold(s) | M51: Lid Mold(s)

Sheet Datasheet (6)
B1: Part Number | D1: Batch Number(s) | F1: ROBAL | H1: Cartridge ID | I1: Initial Weight (mg) | J1: Final Weight (mg) | K1: Weight Loss (mg) | L1: Weight Loss Pass/Fail | M1: Observation
B2: =IF('Datasheet (1)'!B2:C3="","",'Datasheet (1)'!B2:C3) | D2: =IF('Datasheet (1)'!D2:E3="","",'Datasheet (1)'!D2:E3) | F2: =IF('Datasheet (1)'!F2:F3="","",'Datasheet (1)'!F2:F3)
K3: =IF(J3<>"",I3-J3,"") | L3: =IF(J3="","",IF($F$10="","",IF(K3<=$F$10,"PASS","FAIL"))) | M3: =IF(L3="PASS","NA","" )
B5: Cartridge Number (LSP) | D5: NOTE - All weight measurements should be done in "mg" and recorded in "mg". | K5: =IF(J5<>"",I5-J5,"") | L5: =IF(J5="","",IF($F$10="","",IF(K5<=$F$10,"PASS","FAIL"))) | M5: =IF(L5="PASS","NA","")
B6: =IF('Datasheet (1)'!B6:C7="","",'Datasheet (1)'!B6:C7)
K7: =IF(J7<>"",I7-J7,"") | L7: =IF(J7="","",IF($F$10="","",IF(K7<=$F$10,"PASS","FAIL"))) | M7: =IF(L7="PASS","NA","")
B9: PO Number | D9: Assay Family | F9: Weight Loss Spec | K9: =IF(J9<>"",I9-J9,"") | L9: =IF(J9="","",IF($F$10="","",IF(K9<=$F$10,"PASS","FAIL"))) | M9: =IF(L9="PASS","NA","")
B10: =IF('Datasheet (1)'!B10:C11="","",'Datasheet (1)'!B10:C11) | D10: =IF('Datasheet (1)'!D10:E11="","",'Datasheet (1)'!D10:E11) | F10: =IF(OR(D10= "HBV", D10="HCV", D10="HIV", D10="Xpert E-RP"), 15, IF(OR(D10="Norovirus", D10="Strep A", D10="TV", D10="CTNG and Xpress CT/NG", D10="FlexCart-01", D10="FlexCart-05", D10="Flu", D10="BCR-ABL",D10="Breast Cancer", D10="Bladder Cancer", D10="C. Diff", D10="Carba-R", D10="Ebola", D10="FIIFV/Hemosil", D10="FlexCart-02", D10="GBS", D10="HPV", D10="MRSA", D10="MTB", D10="PA", D10="SA Comp", D10="SARS CoV2", D10="Xpress CoV-2 plus",D10="SARS CoV2 Flu/RSV",D10="SARS CoV2 Flu/RSV XC", D10="Xpress CoV-2/Flu/RSV plus",D10="Van A", D10="Xpert Check", D10="Xpert Xpress MVP", D10="Xpert NPM1 Mutation", D10="Xpert Respiratory Panel", D10="Xpert GI Panel", D10="Monkeypox", D10="Xpert PML-RARA RUO", D10="LCE010 Xpress CoV-2/Flu/RSV plus"),100,""))
K11: =IF(J11<>"",I11-J11,"") | L11: =IF(J11="","",IF($F$10="","",IF(K11<=$F$10,"PASS","FAIL"))) | M11: =IF(L11="PASS","NA","")
B13: Balance ID Number | D13: Balance Cal Due Date | K13: =IF(J13<>"",I13-J13,"") | L13: =IF(J13="","",IF($F$10="","",IF(K13<=$F$10,"PASS","FAIL"))) | M13: =IF(L13="PASS","NA","")
K15: =IF(J15<>"",I15-J15,"") | L15: =IF(J15="","",IF($F$10="","",IF(K15<=$F$10,"PASS","FAIL"))) | M15: =IF(L15="PASS","NA","")
K17: =IF(J17<>"",I17-J17,"") | L17: =IF(J17="","",IF($F$10="","",IF(K17<=$F$10,"PASS","FAIL"))) | M17: =IF(L17="PASS","NA","")
B19: Vacuum Oven ID Number | D19: Vacuum Oven Cal Due Date | K19: =IF(J19<>"",I19-J19,"") | L19: =IF(J19="","",IF($F$10="","",IF(K19<=$F$10,"PASS","FAIL"))) | M19: =IF(L19="PASS","NA","")
K21: =IF(J21<>"",I21-J21,"") | L21: =IF(J21="","",IF($F$10="","",IF(K21<=$F$10,"PASS","FAIL"))) | M21: =IF(L21="PASS","NA","")
K23: =IF(J23<>"",I23-J23,"") | L23: =IF(J23="","",IF($F$10="","",IF(K23<=$F$10,"PASS","FAIL"))) | M23: =IF(L23="PASS","NA","")
B24: Timer ID Number | D24: Timer Cal Due Date
K25: =IF(J25<>"",I25-J25,"") | L25: =IF(J25="","",IF($F$10="","",IF(K25<=$F$10,"PASS","FAIL"))) | M25: =IF(L25="PASS","NA","")
K27: =IF(J27<>"",I27-J27,"") | L27: =IF(J27="","",IF($F$10="","",IF(K27<=$F$10,"PASS","FAIL"))) | M27: =IF(L27="PASS","NA","")
B29: Configuration of Cartridge Lid with Chamber Identification | K29: =IF(J29<>"",I29-J29,"") | L29: =IF(J29="","",IF($F$10="","",IF(K29<=$F$10,"PASS","FAIL"))) | M29: =IF(L29="PASS","NA","")
K31: =IF(J31<>"",I31-J31,"") | L31: =IF(J31="","",IF($F$10="","",IF(K31<=$F$10,"PASS","FAIL"))) | M31: =IF(L31="PASS","NA","")
K33: =IF(J33<>"",I33-J33,"") | L33: =IF(J33="","",IF($F$10="","",IF(K33<=$F$10,"PASS","FAIL"))) | M33: =IF(L33="PASS","NA","")
K35: =IF(J35<>"",I35-J35,"") | L35: =IF(J35="","",IF($F$10="","",IF(K35<=$F$10,"PASS","FAIL"))) | M35: =IF(L35="PASS","NA","")
K37: =IF(J37<>"",I37-J37,"") | L37: =IF(J37="","",IF($F$10="","",IF(K37<=$F$10,"PASS","FAIL"))) | M37: =IF(L37="PASS","NA","")
K39: =IF(J39<>"",I39-J39,"") | L39: =IF(J39="","",IF($F$10="","",IF(K39<=$F$10,"PASS","FAIL"))) | M39: =IF(L39="PASS","NA","")
K41: =IF(J41<>"",I41-J41,"") | L41: =IF(J41="","",IF($F$10="","",IF(K41<=$F$10,"PASS","FAIL"))) | M41: =IF(L41="PASS","NA","")
B42: Name of Tester
K43: =IF(J43<>"",I43-J43,"") | L43: =IF(J43="","",IF($F$10="","",IF(K43<=$F$10,"PASS","FAIL"))) | M43: =IF(L43="PASS","NA","")
K45: =IF(J45<>"",I45-J45,"") | L45: =IF(J45="","",IF($F$10="","",IF(K45<=$F$10,"PASS","FAIL"))) | M45: =IF(L45="PASS","NA","")
B46: Signature | D46: Date
B50: Comments | K50: For Information Only
K51: OC Mold(s) | M51: Lid Mold(s)

Sheet Datasheet (7)
B1: Part Number | D1: Batch Number(s) | F1: ROBAL | H1: Cartridge ID | I1: Initial Weight (mg) | J1: Final Weight (mg) | K1: Weight Loss (mg) | L1: Weight Loss Pass/Fail | M1: Observation
B2: =IF('Datasheet (1)'!B2:C3="","",'Datasheet (1)'!B2:C3) | D2: =IF('Datasheet (1)'!D2:E3="","",'Datasheet (1)'!D2:E3) | F2: =IF('Datasheet (1)'!F2:F3="","",'Datasheet (1)'!F2:F3)
K3: =IF(J3<>"",I3-J3,"") | L3: =IF(J3="","",IF($F$10="","",IF(K3<=$F$10,"PASS","FAIL"))) | M3: =IF(L3="PASS","NA","" )
B5: Cartridge Number (LSP) | D5: NOTE - All weight measurements should be done in "mg" and recorded in "mg". | K5: =IF(J5<>"",I5-J5,"") | L5: =IF(J5="","",IF($F$10="","",IF(K5<=$F$10,"PASS","FAIL"))) | M5: =IF(L5="PASS","NA","")
B6: =IF('Datasheet (1)'!B6:C7="","",'Datasheet (1)'!B6:C7)
K7: =IF(J7<>"",I7-J7,"") | L7: =IF(J7="","",IF($F$10="","",IF(K7<=$F$10,"PASS","FAIL"))) | M7: =IF(L7="PASS","NA","")
B9: PO Number | D9: Assay Family | F9: Weight Loss Spec | K9: =IF(J9<>"",I9-J9,"") | L9: =IF(J9="","",IF($F$10="","",IF(K9<=$F$10,"PASS","FAIL"))) | M9: =IF(L9="PASS","NA","")
B10: =IF('Datasheet (1)'!B10:C11="","",'Datasheet (1)'!B10:C11) | D10: =IF('Datasheet (1)'!D10:E11="","",'Datasheet (1)'!D10:E11) | F10: =IF(OR(D10= "HBV", D10="HCV", D10="HIV", D10="Xpert E-RP"), 15, IF(OR(D10="Norovirus", D10="Strep A", D10="TV", D10="CTNG and Xpress CT/NG", D10="FlexCart-01", D10="FlexCart-05", D10="Flu", D10="BCR-ABL",D10="Breast Cancer", D10="Bladder Cancer", D10="C. Diff", D10="Carba-R", D10="Ebola", D10="FIIFV/Hemosil", D10="FlexCart-02", D10="GBS", D10="HPV", D10="MRSA", D10="MTB", D10="PA", D10="SA Comp", D10="SARS CoV2", D10="Xpress CoV-2 plus",D10="SARS CoV2 Flu/RSV",D10="SARS CoV2 Flu/RSV XC", D10="Xpress CoV-2/Flu/RSV plus",D10="Van A", D10="Xpert Check", D10="Xpert Xpress MVP", D10="Xpert NPM1 Mutation", D10="Xpert Respiratory Panel", D10="Xpert GI Panel", D10="Monkeypox", D10="Xpert PML-RARA RUO", D10="LCE010 Xpress CoV-2/Flu/RSV plus"),100,""))
K11: =IF(J11<>"",I11-J11,"") | L11: =IF(J11="","",IF($F$10="","",IF(K11<=$F$10,"PASS","FAIL"))) | M11: =IF(L11="PASS","NA","")
B13: Balance ID Number | D13: Balance Cal Due Date | K13: =IF(J13<>"",I13-J13,"") | L13: =IF(J13="","",IF($F$10="","",IF(K13<=$F$10,"PASS","FAIL"))) | M13: =IF(L13="PASS","NA","")
K15: =IF(J15<>"",I15-J15,"") | L15: =IF(J15="","",IF($F$10="","",IF(K15<=$F$10,"PASS","FAIL"))) | M15: =IF(L15="PASS","NA","")
K17: =IF(J17<>"",I17-J17,"") | L17: =IF(J17="","",IF($F$10="","",IF(K17<=$F$10,"PASS","FAIL"))) | M17: =IF(L17="PASS","NA","")
B19: Vacuum Oven ID Number | D19: Vacuum Oven Cal Due Date | K19: =IF(J19<>"",I19-J19,"") | L19: =IF(J19="","",IF($F$10="","",IF(K19<=$F$10,"PASS","FAIL"))) | M19: =IF(L19="PASS","NA","")
K21: =IF(J21<>"",I21-J21,"") | L21: =IF(J21="","",IF($F$10="","",IF(K21<=$F$10,"PASS","FAIL"))) | M21: =IF(L21="PASS","NA","")
K23: =IF(J23<>"",I23-J23,"") | L23: =IF(J23="","",IF($F$10="","",IF(K23<=$F$10,"PASS","FAIL"))) | M23: =IF(L23="PASS","NA","")
B24: Timer ID Number | D24: Timer Cal Due Date
K25: =IF(J25<>"",I25-J25,"") | L25: =IF(J25="","",IF($F$10="","",IF(K25<=$F$10,"PASS","FAIL"))) | M25: =IF(L25="PASS","NA","")
K27: =IF(J27<>"",I27-J27,"") | L27: =IF(J27="","",IF($F$10="","",IF(K27<=$F$10,"PASS","FAIL"))) | M27: =IF(L27="PASS","NA","")
B29: Configuration of Cartridge Lid with Chamber Identification | K29: =IF(J29<>"",I29-J29,"") | L29: =IF(J29="","",IF($F$10="","",IF(K29<=$F$10,"PASS","FAIL"))) | M29: =IF(L29="PASS","NA","")
K31: =IF(J31<>"",I31-J31,"") | L31: =IF(J31="","",IF($F$10="","",IF(K31<=$F$10,"PASS","FAIL"))) | M31: =IF(L31="PASS","NA","")
K33: =IF(J33<>"",I33-J33,"") | L33: =IF(J33="","",IF($F$10="","",IF(K33<=$F$10,"PASS","FAIL"))) | M33: =IF(L33="PASS","NA","")
K35: =IF(J35<>"",I35-J35,"") | L35: =IF(J35="","",IF($F$10="","",IF(K35<=$F$10,"PASS","FAIL"))) | M35: =IF(L35="PASS","NA","")
K37: =IF(J37<>"",I37-J37,"") | L37: =IF(J37="","",IF($F$10="","",IF(K37<=$F$10,"PASS","FAIL"))) | M37: =IF(L37="PASS","NA","")
K39: =IF(J39<>"",I39-J39,"") | L39: =IF(J39="","",IF($F$10="","",IF(K39<=$F$10,"PASS","FAIL"))) | M39: =IF(L39="PASS","NA","")
K41: =IF(J41<>"",I41-J41,"") | L41: =IF(J41="","",IF($F$10="","",IF(K41<=$F$10,"PASS","FAIL"))) | M41: =IF(L41="PASS","NA","")
B42: Name of Tester
K43: =IF(J43<>"",I43-J43,"") | L43: =IF(J43="","",IF($F$10="","",IF(K43<=$F$10,"PASS","FAIL"))) | M43: =IF(L43="PASS","NA","")
K45: =IF(J45<>"",I45-J45,"") | L45: =IF(J45="","",IF($F$10="","",IF(K45<=$F$10,"PASS","FAIL"))) | M45: =IF(L45="PASS","NA","")
B46: Signature | D46: Date
B50: Comments | K50: For Information Only
K51: OC Mold(s) | M51: Lid Mold(s)

Sheet Datasheet (8)
B1: Part Number | D1: Batch Number(s) | F1: ROBAL | H1: Cartridge ID | I1: Initial Weight (mg) | J1: Final Weight (mg) | K1: Weight Loss (mg) | L1: Weight Loss Pass/Fail | M1: Observation
B2: =IF('Datasheet (1)'!B2:C3="","",'Datasheet (1)'!B2:C3) | D2: =IF('Datasheet (1)'!D2:E3="","",'Datasheet (1)'!D2:E3) | F2: =IF('Datasheet (1)'!F2:F3="","",'Datasheet (1)'!F2:F3)
K3: =IF(J3<>"",I3-J3,"") | L3: =IF(J3="","",IF($F$10="","",IF(K3<=$F$10,"PASS","FAIL"))) | M3: =IF(L3="PASS","NA","" )
B5: Cartridge Number (LSP) | D5: NOTE - All weight measurements should be done in "mg" and recorded in "mg". | K5: =IF(J5<>"",I5-J5,"") | L5: =IF(J5="","",IF($F$10="","",IF(K5<=$F$10,"PASS","FAIL"))) | M5: =IF(L5="PASS","NA","")
B6: =IF('Datasheet (1)'!B6:C7="","",'Datasheet (1)'!B6:C7)
K7: =IF(J7<>"",I7-J7,"") | L7: =IF(J7="","",IF($F$10="","",IF(K7<=$F$10,"PASS","FAIL"))) | M7: =IF(L7="PASS","NA","")
B9: PO Number | D9: Assay Family | F9: Weight Loss Spec | K9: =IF(J9<>"",I9-J9,"") | L9: =IF(J9="","",IF($F$10="","",IF(K9<=$F$10,"PASS","FAIL"))) | M9: =IF(L9="PASS","NA","")
B10: =IF('Datasheet (1)'!B10:C11="","",'Datasheet (1)'!B10:C11) | D10: =IF('Datasheet (1)'!D10:E11="","",'Datasheet (1)'!D10:E11) | F10: =IF(OR(D10= "HBV", D10="HCV", D10="HIV", D10="Xpert E-RP"), 15, IF(OR(D10="Norovirus", D10="Strep A", D10="TV", D10="CTNG and Xpress CT/NG", D10="FlexCart-01", D10="FlexCart-05", D10="Flu", D10="BCR-ABL",D10="Breast Cancer", D10="Bladder Cancer", D10="C. Diff", D10="Carba-R", D10="Ebola", D10="FIIFV/Hemosil", D10="FlexCart-02", D10="GBS", D10="HPV", D10="MRSA", D10="MTB", D10="PA", D10="SA Comp", D10="SARS CoV2", D10="Xpress CoV-2 plus",D10="SARS CoV2 Flu/RSV",D10="SARS CoV2 Flu/RSV XC", D10="Xpress CoV-2/Flu/RSV plus",D10="Van A", D10="Xpert Check", D10="Xpert Xpress MVP", D10="Xpert NPM1 Mutation", D10="Xpert Respiratory Panel", D10="Xpert GI Panel", D10="Monkeypox", D10="Xpert PML-RARA RUO", D10="LCE010 Xpress CoV-2/Flu/RSV plus"),100,""))
K11: =IF(J11<>"",I11-J11,"") | L11: =IF(J11="","",IF($F$10="","",IF(K11<=$F$10,"PASS","FAIL"))) | M11: =IF(L11="PASS","NA","")
B13: Balance ID Number | D13: Balance Cal Due Date | K13: =IF(J13<>"",I13-J13,"") | L13: =IF(J13="","",IF($F$10="","",IF(K13<=$F$10,"PASS","FAIL"))) | M13: =IF(L13="PASS","NA","")
K15: =IF(J15<>"",I15-J15,"") | L15: =IF(J15="","",IF($F$10="","",IF(K15<=$F$10,"PASS","FAIL"))) | M15: =IF(L15="PASS","NA","")
K17: =IF(J17<>"",I17-J17,"") | L17: =IF(J17="","",IF($F$10="","",IF(K17<=$F$10,"PASS","FAIL"))) | M17: =IF(L17="PASS","NA","")
B19: Vacuum Oven ID Number | D19: Vacuum Oven Cal Due Date | K19: =IF(J19<>"",I19-J19,"") | L19: =IF(J19="","",IF($F$10="","",IF(K19<=$F$10,"PASS","FAIL"))) | M19: =IF(L19="PASS","NA","")
K21: =IF(J21<>"",I21-J21,"") | L21: =IF(J21="","",IF($F$10="","",IF(K21<=$F$10,"PASS","FAIL"))) | M21: =IF(L21="PASS","NA","")
K23: =IF(J23<>"",I23-J23,"") | L23: =IF(J23="","",IF($F$10="","",IF(K23<=$F$10,"PASS","FAIL"))) | M23: =IF(L23="PASS","NA","")
B24: Timer ID Number | D24: Timer Cal Due Date
K25: =IF(J25<>"",I25-J25,"") | L25: =IF(J25="","",IF($F$10="","",IF(K25<=$F$10,"PASS","FAIL"))) | M25: =IF(L25="PASS","NA","")
K27: =IF(J27<>"",I27-J27,"") | L27: =IF(J27="","",IF($F$10="","",IF(K27<=$F$10,"PASS","FAIL"))) | M27: =IF(L27="PASS","NA","")
B29: Configuration of Cartridge Lid with Chamber Identification | K29: =IF(J29<>"",I29-J29,"") | L29: =IF(J29="","",IF($F$10="","",IF(K29<=$F$10,"PASS","FAIL"))) | M29: =IF(L29="PASS","NA","")
K31: =IF(J31<>"",I31-J31,"") | L31: =IF(J31="","",IF($F$10="","",IF(K31<=$F$10,"PASS","FAIL"))) | M31: =IF(L31="PASS","NA","")
K33: =IF(J33<>"",I33-J33,"") | L33: =IF(J33="","",IF($F$10="","",IF(K33<=$F$10,"PASS","FAIL"))) | M33: =IF(L33="PASS","NA","")
K35: =IF(J35<>"",I35-J35,"") | L35: =IF(J35="","",IF($F$10="","",IF(K35<=$F$10,"PASS","FAIL"))) | M35: =IF(L35="PASS","NA","")
K37: =IF(J37<>"",I37-J37,"") | L37: =IF(J37="","",IF($F$10="","",IF(K37<=$F$10,"PASS","FAIL"))) | M37: =IF(L37="PASS","NA","")
K39: =IF(J39<>"",I39-J39,"") | L39: =IF(J39="","",IF($F$10="","",IF(K39<=$F$10,"PASS","FAIL"))) | M39: =IF(L39="PASS","NA","")
K41: =IF(J41<>"",I41-J41,"") | L41: =IF(J41="","",IF($F$10="","",IF(K41<=$F$10,"PASS","FAIL"))) | M41: =IF(L41="PASS","NA","")
B42: Name of Tester
K43: =IF(J43<>"",I43-J43,"") | L43: =IF(J43="","",IF($F$10="","",IF(K43<=$F$10,"PASS","FAIL"))) | M43: =IF(L43="PASS","NA","")
K45: =IF(J45<>"",I45-J45,"") | L45: =IF(J45="","",IF($F$10="","",IF(K45<=$F$10,"PASS","FAIL"))) | M45: =IF(L45="PASS","NA","")
B46: Signature | D46: Date
B50: Comments | K50: For Information Only
K51: OC Mold(s) | M51: Lid Mold(s)

Sheet Datasheet (9)
B1: Part Number | D1: Batch Number(s) | F1: ROBAL | H1: Cartridge ID | I1: Initial Weight (mg) | J1: Final Weight (mg) | K1: Weight Loss (mg) | L1: Weight Loss Pass/Fail | M1: Observation
B2: =IF('Datasheet (1)'!B2:C3="","",'Datasheet (1)'!B2:C3) | D2: =IF('Datasheet (1)'!D2:E3="","",'Datasheet (1)'!D2:E3) | F2: =IF('Datasheet (1)'!F2:F3="","",'Datasheet (1)'!F2:F3)
K3: =IF(J3<>"",I3-J3,"") | L3: =IF(J3="","",IF($F$10="","",IF(K3<=$F$10,"PASS","FAIL"))) | M3: =IF(L3="PASS","NA","" )
B5: Cartridge Number (LSP) | D5: NOTE - All weight measurements should be done in "mg" and recorded in "mg". | K5: =IF(J5<>"",I5-J5,"") | L5: =IF(J5="","",IF($F$10="","",IF(K5<=$F$10,"PASS","FAIL"))) | M5: =IF(L5="PASS","NA","")
B6: =IF('Datasheet (1)'!B6:C7="","",'Datasheet (1)'!B6:C7)
K7: =IF(J7<>"",I7-J7,"") | L7: =IF(J7="","",IF($F$10="","",IF(K7<=$F$10,"PASS","FAIL"))) | M7: =IF(L7="PASS","NA","")
B9: PO Number | D9: Assay Family | F9: Weight Loss Spec | K9: =IF(J9<>"",I9-J9,"") | L9: =IF(J9="","",IF($F$10="","",IF(K9<=$F$10,"PASS","FAIL"))) | M9: =IF(L9="PASS","NA","")
B10: =IF('Datasheet (1)'!B10:C11="","",'Datasheet (1)'!B10:C11) | D10: =IF('Datasheet (1)'!D10:E11="","",'Datasheet (1)'!D10:E11) | F10: =IF(OR(D10= "HBV", D10="HCV", D10="HIV", D10="Xpert E-RP"), 15, IF(OR(D10="Norovirus", D10="Strep A", D10="TV", D10="CTNG and Xpress CT/NG", D10="FlexCart-01", D10="FlexCart-05", D10="Flu", D10="BCR-ABL",D10="Breast Cancer", D10="Bladder Cancer", D10="C. Diff", D10="Carba-R", D10="Ebola", D10="FIIFV/Hemosil", D10="FlexCart-02", D10="GBS", D10="HPV", D10="MRSA", D10="MTB", D10="PA", D10="SA Comp", D10="SARS CoV2", D10="Xpress CoV-2 plus",D10="SARS CoV2 Flu/RSV",D10="SARS CoV2 Flu/RSV XC", D10="Xpress CoV-2/Flu/RSV plus",D10="Van A", D10="Xpert Check", D10="Xpert Xpress MVP", D10="Xpert NPM1 Mutation", D10="Xpert Respiratory Panel", D10="Xpert GI Panel", D10="Monkeypox", D10="Xpert PML-RARA RUO", D10="LCE010 Xpress CoV-2/Flu/RSV plus"),100,""))
K11: =IF(J11<>"",I11-J11,"") | L11: =IF(J11="","",IF($F$10="","",IF(K11<=$F$10,"PASS","FAIL"))) | M11: =IF(L11="PASS","NA","")
B13: Balance ID Number | D13: Balance Cal Due Date | K13: =IF(J13<>"",I13-J13,"") | L13: =IF(J13="","",IF($F$10="","",IF(K13<=$F$10,"PASS","FAIL"))) | M13: =IF(L13="PASS","NA","")
K15: =IF(J15<>"",I15-J15,"") | L15: =IF(J15="","",IF($F$10="","",IF(K15<=$F$10,"PASS","FAIL"))) | M15: =IF(L15="PASS","NA","")
K17: =IF(J17<>"",I17-J17,"") | L17: =IF(J17="","",IF($F$10="","",IF(K17<=$F$10,"PASS","FAIL"))) | M17: =IF(L17="PASS","NA","")
B19: Vacuum Oven ID Number | D19: Vacuum Oven Cal Due Date | K19: =IF(J19<>"",I19-J19,"") | L19: =IF(J19="","",IF($F$10="","",IF(K19<=$F$10,"PASS","FAIL"))) | M19: =IF(L19="PASS","NA","")
K21: =IF(J21<>"",I21-J21,"") | L21: =IF(J21="","",IF($F$10="","",IF(K21<=$F$10,"PASS","FAIL"))) | M21: =IF(L21="PASS","NA","")
K23: =IF(J23<>"",I23-J23,"") | L23: =IF(J23="","",IF($F$10="","",IF(K23<=$F$10,"PASS","FAIL"))) | M23: =IF(L23="PASS","NA","")
B24: Timer ID Number | D24: Timer Cal Due Date
K25: =IF(J25<>"",I25-J25,"") | L25: =IF(J25="","",IF($F$10="","",IF(K25<=$F$10,"PASS","FAIL"))) | M25: =IF(L25="PASS","NA","")
K27: =IF(J27<>"",I27-J27,"") | L27: =IF(J27="","",IF($F$10="","",IF(K27<=$F$10,"PASS","FAIL"))) | M27: =IF(L27="PASS","NA","")
B29: Configuration of Cartridge Lid with Chamber Identification | K29: =IF(J29<>"",I29-J29,"") | L29: =IF(J29="","",IF($F$10="","",IF(K29<=$F$10,"PASS","FAIL"))) | M29: =IF(L29="PASS","NA","")
K31: =IF(J31<>"",I31-J31,"") | L31: =IF(J31="","",IF($F$10="","",IF(K31<=$F$10,"PASS","FAIL"))) | M31: =IF(L31="PASS","NA","")
K33: =IF(J33<>"",I33-J33,"") | L33: =IF(J33="","",IF($F$10="","",IF(K33<=$F$10,"PASS","FAIL"))) | M33: =IF(L33="PASS","NA","")
K35: =IF(J35<>"",I35-J35,"") | L35: =IF(J35="","",IF($F$10="","",IF(K35<=$F$10,"PASS","FAIL"))) | M35: =IF(L35="PASS","NA","")
K37: =IF(J37<>"",I37-J37,"") | L37: =IF(J37="","",IF($F$10="","",IF(K37<=$F$10,"PASS","FAIL"))) | M37: =IF(L37="PASS","NA","")
K39: =IF(J39<>"",I39-J39,"") | L39: =IF(J39="","",IF($F$10="","",IF(K39<=$F$10,"PASS","FAIL"))) | M39: =IF(L39="PASS","NA","")
K41: =IF(J41<>"",I41-J41,"") | L41: =IF(J41="","",IF($F$10="","",IF(K41<=$F$10,"PASS","FAIL"))) | M41: =IF(L41="PASS","NA","")
B42: Name of Tester
K43: =IF(J43<>"",I43-J43,"") | L43: =IF(J43="","",IF($F$10="","",IF(K43<=$F$10,"PASS","FAIL"))) | M43: =IF(L43="PASS","NA","")
K45: =IF(J45<>"",I45-J45,"") | L45: =IF(J45="","",IF($F$10="","",IF(K45<=$F$10,"PASS","FAIL"))) | M45: =IF(L45="PASS","NA","")
B46: Signature | D46: Date
B50: Comments | K50: For Information Only
K51: OC Mold(s) | M51: Lid Mold(s)

Sheet Datasheet (10)
B1: Part Number | D1: Batch Number(s) | F1: ROBAL | H1: Cartridge ID | I1: Initial Weight (mg) | J1: Final Weight (mg) | K1: Weight Loss (mg) | L1: Weight Loss Pass/Fail | M1: Observation
B2: =IF('Datasheet (1)'!B2:C3="","",'Datasheet (1)'!B2:C3) | D2: =IF('Datasheet (1)'!D2:E3="","",'Datasheet (1)'!D2:E3) | F2: =IF('Datasheet (1)'!F2:F3="","",'Datasheet (1)'!F2:F3)
K3: =IF(J3<>"",I3-J3,"") | L3: =IF(J3="","",IF($F$10="","",IF(K3<=$F$10,"PASS","FAIL"))) | M3: =IF(L3="PASS","NA","" )
B5: Cartridge Number (LSP) | D5: NOTE - All weight measurements should be done in "mg" and recorded in "mg". | K5: =IF(J5<>"",I5-J5,"") | L5: =IF(J5="","",IF($F$10="","",IF(K5<=$F$10,"PASS","FAIL"))) | M5: =IF(L5="PASS","NA","")
B6: =IF('Datasheet (1)'!B6:C7="","",'Datasheet (1)'!B6:C7)
K7: =IF(J7<>"",I7-J7,"") | L7: =IF(J7="","",IF($F$10="","",IF(K7<=$F$10,"PASS","FAIL"))) | M7: =IF(L7="PASS","NA","")
B9: PO Number | D9: Assay Family | F9: Weight Loss Spec | K9: =IF(J9<>"",I9-J9,"") | L9: =IF(J9="","",IF($F$10="","",IF(K9<=$F$10,"PASS","FAIL"))) | M9: =IF(L9="PASS","NA","")
B10: =IF('Datasheet (1)'!B10:C11="","",'Datasheet (1)'!B10:C11) | D10: =IF('Datasheet (1)'!D10:E11="","",'Datasheet (1)'!D10:E11) | F10: =IF(OR(D10= "HBV", D10="HCV", D10="HIV", D10="Xpert E-RP"), 15, IF(OR(D10="Norovirus", D10="Strep A", D10="TV", D10="CTNG and Xpress CT/NG", D10="FlexCart-01", D10="FlexCart-05", D10="Flu", D10="BCR-ABL",D10="Breast Cancer", D10="Bladder Cancer", D10="C. Diff", D10="Carba-R", D10="Ebola", D10="FIIFV/Hemosil", D10="FlexCart-02", D10="GBS", D10="HPV", D10="MRSA", D10="MTB", D10="PA", D10="SA Comp", D10="SARS CoV2", D10="Xpress CoV-2 plus",D10="SARS CoV2 Flu/RSV",D10="SARS CoV2 Flu/RSV XC", D10="Xpress CoV-2/Flu/RSV plus",D10="Van A", D10="Xpert Check", D10="Xpert Xpress MVP", D10="Xpert NPM1 Mutation", D10="Xpert Respiratory Panel", D10="Xpert GI Panel", D10="Monkeypox", D10="Xpert PML-RARA RUO", D10="LCE010 Xpress CoV-2/Flu/RSV plus"),100,""))
K11: =IF(J11<>"",I11-J11,"") | L11: =IF(J11="","",IF($F$10="","",IF(K11<=$F$10,"PASS","FAIL"))) | M11: =IF(L11="PASS","NA","")
B13: Balance ID Number | D13: Balance Cal Due Date | K13: =IF(J13<>"",I13-J13,"") | L13: =IF(J13="","",IF($F$10="","",IF(K13<=$F$10,"PASS","FAIL"))) | M13: =IF(L13="PASS","NA","")
K15: =IF(J15<>"",I15-J15,"") | L15: =IF(J15="","",IF($F$10="","",IF(K15<=$F$10,"PASS","FAIL"))) | M15: =IF(L15="PASS","NA","")
K17: =IF(J17<>"",I17-J17,"") | L17: =IF(J17="","",IF($F$10="","",IF(K17<=$F$10,"PASS","FAIL"))) | M17: =IF(L17="PASS","NA","")
B19: Vacuum Oven ID Number | D19: Vacuum Oven Cal Due Date | K19: =IF(J19<>"",I19-J19,"") | L19: =IF(J19="","",IF($F$10="","",IF(K19<=$F$10,"PASS","FAIL"))) | M19: =IF(L19="PASS","NA","")
K21: =IF(J21<>"",I21-J21,"") | L21: =IF(J21="","",IF($F$10="","",IF(K21<=$F$10,"PASS","FAIL"))) | M21: =IF(L21="PASS","NA","")
K23: =IF(J23<>"",I23-J23,"") | L23: =IF(J23="","",IF($F$10="","",IF(K23<=$F$10,"PASS","FAIL"))) | M23: =IF(L23="PASS","NA","")
B24: Timer ID Number | D24: Timer Cal Due Date
K25: =IF(J25<>"",I25-J25,"") | L25: =IF(J25="","",IF($F$10="","",IF(K25<=$F$10,"PASS","FAIL"))) | M25: =IF(L25="PASS","NA","")
K27: =IF(J27<>"",I27-J27,"") | L27: =IF(J27="","",IF($F$10="","",IF(K27<=$F$10,"PASS","FAIL"))) | M27: =IF(L27="PASS","NA","")
B29: Configuration of Cartridge Lid with Chamber Identification | K29: =IF(J29<>"",I29-J29,"") | L29: =IF(J29="","",IF($F$10="","",IF(K29<=$F$10,"PASS","FAIL"))) | M29: =IF(L29="PASS","NA","")
K31: =IF(J31<>"",I31-J31,"") | L31: =IF(J31="","",IF($F$10="","",IF(K31<=$F$10,"PASS","FAIL"))) | M31: =IF(L31="PASS","NA","")
K33: =IF(J33<>"",I33-J33,"") | L33: =IF(J33="","",IF($F$10="","",IF(K33<=$F$10,"PASS","FAIL"))) | M33: =IF(L33="PASS","NA","")
K35: =IF(J35<>"",I35-J35,"") | L35: =IF(J35="","",IF($F$10="","",IF(K35<=$F$10,"PASS","FAIL"))) | M35: =IF(L35="PASS","NA","")
K37: =IF(J37<>"",I37-J37,"") | L37: =IF(J37="","",IF($F$10="","",IF(K37<=$F$10,"PASS","FAIL"))) | M37: =IF(L37="PASS","NA","")
K39: =IF(J39<>"",I39-J39,"") | L39: =IF(J39="","",IF($F$10="","",IF(K39<=$F$10,"PASS","FAIL"))) | M39: =IF(L39="PASS","NA","")
K41: =IF(J41<>"",I41-J41,"") | L41: =IF(J41="","",IF($F$10="","",IF(K41<=$F$10,"PASS","FAIL"))) | M41: =IF(L41="PASS","NA","")
B42: Name of Tester
K43: =IF(J43<>"",I43-J43,"") | L43: =IF(J43="","",IF($F$10="","",IF(K43<=$F$10,"PASS","FAIL"))) | M43: =IF(L43="PASS","NA","")
K45: =IF(J45<>"",I45-J45,"") | L45: =IF(J45="","",IF($F$10="","",IF(K45<=$F$10,"PASS","FAIL"))) | M45: =IF(L45="PASS","NA","")
B46: Signature | D46: Date
B50: Comments | K50: For Information Only
K51: OC Mold(s) | M51: Lid Mold(s)

Sheet Replacement Cartridge (11)
B1: Part Number | D1: Batch Number(s) | F1: ROBAL | H1: Cartridge ID | I1: Initial Weight (mg) | J1: Final Weight (mg) | K1: Weight Loss (mg) | L1: Weight Loss Pass/Fail | M1: Observation
B2: =IF('Datasheet (1)'!B2:C3="","",'Datasheet (1)'!B2:C3) | D2: =IF('Datasheet (1)'!D2:E3="","",'Datasheet (1)'!D2:E3) | F2: =IF('Datasheet (1)'!F2:F3="","",'Datasheet (1)'!F2:F3)
K3: =IF(J3<>"",I3-J3,"") | L3: =IF(J3="","",IF($F$10="","",IF(K3<=$F$10,"PASS","FAIL"))) | M3: =IF(L3="PASS","NA","" )
B5: Cartridge Number (LSP) | D5: NOTE - All weight measurements should be done in "mg" and recorded in "mg". | K5: =IF(J5<>"",I5-J5,"") | L5: =IF(J5="","",IF($F$10="","",IF(K5<=$F$10,"PASS","FAIL"))) | M5: =IF(L5="PASS","NA","")
B6: =IF('Datasheet (1)'!B6:C7="","",'Datasheet (1)'!B6:C7)
K7: =IF(J7<>"",I7-J7,"") | L7: =IF(J7="","",IF($F$10="","",IF(K7<=$F$10,"PASS","FAIL"))) | M7: =IF(L7="PASS","NA","")
B9: PO Number | D9: Assay Family | F9: Weight Loss Spec | K9: =IF(J9<>"",I9-J9,"") | L9: =IF(J9="","",IF($F$10="","",IF(K9<=$F$10,"PASS","FAIL"))) | M9: =IF(L9="PASS","NA","")
B10: =IF('Datasheet (1)'!B10:C11="","",'Datasheet (1)'!B10:C11) | D10: =IF('Datasheet (1)'!D10:E11="","",'Datasheet (1)'!D10:E11) | F10: =IF(OR(D10= "HBV", D10="HCV", D10="HIV", D10="Xpert E-RP"), 15, IF(OR(D10="Norovirus", D10="Strep A", D10="TV", D10="CTNG and Xpress CT/NG", D10="FlexCart-01", D10="FlexCart-05", D10="Flu", D10="BCR-ABL",D10="Breast Cancer", D10="Bladder Cancer", D10="C. Diff", D10="Carba-R", D10="Ebola", D10="FIIFV/Hemosil", D10="FlexCart-02", D10="GBS", D10="HPV", D10="MRSA", D10="MTB", D10="PA", D10="SA Comp", D10="SARS CoV2", D10="Xpress CoV-2 plus",D10="SARS CoV2 Flu/RSV",D10="SARS CoV2 Flu/RSV XC", D10="Xpress CoV-2/Flu/RSV plus",D10="Van A", D10="Xpert Check", D10="Xpert Xpress MVP", D10="Xpert NPM1 Mutation", D10="Xpert Respiratory Panel", D10="Xpert GI Panel", D10="Monkeypox", D10="Xpert PML-RARA RUO", D10="LCE010 Xpress CoV-2/Flu/RSV plus"),100,""))
K11: =IF(J11<>"",I11-J11,"") | L11: =IF(J11="","",IF($F$10="","",IF(K11<=$F$10,"PASS","FAIL"))) | M11: =IF(L11="PASS","NA","")
B13: Balance ID Number | D13: Balance Cal Due Date | K13: =IF(J13<>"",I13-J13,"") | L13: =IF(J13="","",IF($F$10="","",IF(K13<=$F$10,"PASS","FAIL"))) | M13: =IF(L13="PASS","NA","")
K15: =IF(J15<>"",I15-J15,"") | L15: =IF(J15="","",IF($F$10="","",IF(K15<=$F$10,"PASS","FAIL"))) | M15: =IF(L15="PASS","NA","")
K17: =IF(J17<>"",I17-J17,"") | L17: =IF(J17="","",IF($F$10="","",IF(K17<=$F$10,"PASS","FAIL"))) | M17: =IF(L17="PASS","NA","")
B19: Vacuum Oven ID Number | D19: Vacuum Oven Cal Due Date | K19: =IF(J19<>"",I19-J19,"") | L19: =IF(J19="","",IF($F$10="","",IF(K19<=$F$10,"PASS","FAIL"))) | M19: =IF(L19="PASS","NA","")
K21: =IF(J21<>"",I21-J21,"") | L21: =IF(J21="","",IF($F$10="","",IF(K21<=$F$10,"PASS","FAIL"))) | M21: =IF(L21="PASS","NA","")
K23: =IF(J23<>"",I23-J23,"") | L23: =IF(J23="","",IF($F$10="","",IF(K23<=$F$10,"PASS","FAIL"))) | M23: =IF(L23="PASS","NA","")
B24: Timer ID Number | D24: Timer Cal Due Date
K25: =IF(J25<>"",I25-J25,"") | L25: =IF(J25="","",IF($F$10="","",IF(K25<=$F$10,"PASS","FAIL"))) | M25: =IF(L25="PASS","NA","")
K27: =IF(J27<>"",I27-J27,"") | L27: =IF(J27="","",IF($F$10="","",IF(K27<=$F$10,"PASS","FAIL"))) | M27: =IF(L27="PASS","NA","")
B29: Configuration of Cartridge Lid with Chamber Identification | K29: =IF(J29<>"",I29-J29,"") | L29: =IF(J29="","",IF($F$10="","",IF(K29<=$F$10,"PASS","FAIL"))) | M29: =IF(L29="PASS","NA","")
K31: =IF(J31<>"",I31-J31,"") | L31: =IF(J31="","",IF($F$10="","",IF(K31<=$F$10,"PASS","FAIL"))) | M31: =IF(L31="PASS","NA","")
K33: =IF(J33<>"",I33-J33,"") | L33: =IF(J33="","",IF($F$10="","",IF(K33<=$F$10,"PASS","FAIL"))) | M33: =IF(L33="PASS","NA","")
K35: =IF(J35<>"",I35-J35,"") | L35: =IF(J35="","",IF($F$10="","",IF(K35<=$F$10,"PASS","FAIL"))) | M35: =IF(L35="PASS","NA","")
K37: =IF(J37<>"",I37-J37,"") | L37: =IF(J37="","",IF($F$10="","",IF(K37<=$F$10,"PASS","FAIL"))) | M37: =IF(L37="PASS","NA","")
K39: =IF(J39<>"",I39-J39,"") | L39: =IF(J39="","",IF($F$10="","",IF(K39<=$F$10,"PASS","FAIL"))) | M39: =IF(L39="PASS","NA","")
K41: =IF(J41<>"",I41-J41,"") | L41: =IF(J41="","",IF($F$10="","",IF(K41<=$F$10,"PASS","FAIL"))) | M41: =IF(L41="PASS","NA","")
B42: Name of Tester
K43: =IF(J43<>"",I43-J43,"") | L43: =IF(J43="","",IF($F$10="","",IF(K43<=$F$10,"PASS","FAIL"))) | M43: =IF(L43="PASS","NA","")
K45: =IF(J45<>"",I45-J45,"") | L45: =IF(J45="","",IF($F$10="","",IF(K45<=$F$10,"PASS","FAIL"))) | M45: =IF(L45="PASS","NA","")
B46: Signature | D46: Date
B50: Comments | K50: For Information Only
K51: OC Mold(s) | M51: Lid Mold(s)

Sheet Replacement Cartridge (12)
B1: Part Number | D1: Batch Number(s) | F1: ROBAL | H1: Cartridge ID | I1: Initial Weight (mg) | J1: Final Weight (mg) | K1: Weight Loss (mg) | L1: Weight Loss Pass/Fail | M1: Observation
B2: =IF('Datasheet (1)'!B2:C3="","",'Datasheet (1)'!B2:C3) | D2: =IF('Datasheet (1)'!D2:E3="","",'Datasheet (1)'!D2:E3) | F2: =IF('Datasheet (1)'!F2:F3="","",'Datasheet (1)'!F2:F3)
K3: =IF(J3<>"",I3-J3,"") | L3: =IF(J3="","",IF($F$10="","",IF(K3<=$F$10,"PASS","FAIL"))) | M3: =IF(L3="PASS","NA","" )
B5: Cartridge Number (LSP) | D5: NOTE - All weight measurements should be done in "mg" and recorded in "mg". | K5: =IF(J5<>"",I5-J5,"") | L5: =IF(J5="","",IF($F$10="","",IF(K5<=$F$10,"PASS","FAIL"))) | M5: =IF(L5="PASS","NA","")
B6: =IF('Datasheet (1)'!B6:C7="","",'Datasheet (1)'!B6:C7)
K7: =IF(J7<>"",I7-J7,"") | L7: =IF(J7="","",IF($F$10="","",IF(K7<=$F$10,"PASS","FAIL"))) | M7: =IF(L7="PASS","NA","")
B9: PO Number | D9: Assay Family | F9: Weight Loss Spec | K9: =IF(J9<>"",I9-J9,"") | L9: =IF(J9="","",IF($F$10="","",IF(K9<=$F$10,"PASS","FAIL"))) | M9: =IF(L9="PASS","NA","")
B10: =IF('Datasheet (1)'!B10:C11="","",'Datasheet (1)'!B10:C11) | D10: =IF('Datasheet (1)'!D10:E11="","",'Datasheet (1)'!D10:E11) | F10: =IF(OR(D10= "HBV", D10="HCV", D10="HIV", D10="Xpert E-RP"), 15, IF(OR(D10="Norovirus", D10="Strep A", D10="TV", D10="CTNG and Xpress CT/NG", D10="FlexCart-01", D10="FlexCart-05", D10="Flu", D10="BCR-ABL",D10="Breast Cancer", D10="Bladder Cancer", D10="C. Diff", D10="Carba-R", D10="Ebola", D10="FIIFV/Hemosil", D10="FlexCart-02", D10="GBS", D10="HPV", D10="MRSA", D10="MTB", D10="PA", D10="SA Comp", D10="SARS CoV2", D10="Xpress CoV-2 plus",D10="SARS CoV2 Flu/RSV",D10="SARS CoV2 Flu/RSV XC", D10="Xpress CoV-2/Flu/RSV plus",D10="Van A", D10="Xpert Check", D10="Xpert Xpress MVP", D10="Xpert NPM1 Mutation", D10="Xpert Respiratory Panel", D10="Xpert GI Panel", D10="Monkeypox", D10="Xpert PML-RARA RUO", D10="LCE010 Xpress CoV-2/Flu/RSV plus"),100,""))
K11: =IF(J11<>"",I11-J11,"") | L11: =IF(J11="","",IF($F$10="","",IF(K11<=$F$10,"PASS","FAIL"))) | M11: =IF(L11="PASS","NA","")
B13: Balance ID Number | D13: Balance Cal Due Date | K13: =IF(J13<>"",I13-J13,"") | L13: =IF(J13="","",IF($F$10="","",IF(K13<=$F$10,"PASS","FAIL"))) | M13: =IF(L13="PASS","NA","")
K15: =IF(J15<>"",I15-J15,"") | L15: =IF(J15="","",IF($F$10="","",IF(K15<=$F$10,"PASS","FAIL"))) | M15: =IF(L15="PASS","NA","")
K17: =IF(J17<>"",I17-J17,"") | L17: =IF(J17="","",IF($F$10="","",IF(K17<=$F$10,"PASS","FAIL"))) | M17: =IF(L17="PASS","NA","")
B19: Vacuum Oven ID Number | D19: Vacuum Oven Cal Due Date | K19: =IF(J19<>"",I19-J19,"") | L19: =IF(J19="","",IF($F$10="","",IF(K19<=$F$10,"PASS","FAIL"))) | M19: =IF(L19="PASS","NA","")
K21: =IF(J21<>"",I21-J21,"") | L21: =IF(J21="","",IF($F$10="","",IF(K21<=$F$10,"PASS","FAIL"))) | M21: =IF(L21="PASS","NA","")
K23: =IF(J23<>"",I23-J23,"") | L23: =IF(J23="","",IF($F$10="","",IF(K23<=$F$10,"PASS","FAIL"))) | M23: =IF(L23="PASS","NA","")
B24: Timer ID Number | D24: Timer Cal Due Date
K25: =IF(J25<>"",I25-J25,"") | L25: =IF(J25="","",IF($F$10="","",IF(K25<=$F$10,"PASS","FAIL"))) | M25: =IF(L25="PASS","NA","")
K27: =IF(J27<>"",I27-J27,"") | L27: =IF(J27="","",IF($F$10="","",IF(K27<=$F$10,"PASS","FAIL"))) | M27: =IF(L27="PASS","NA","")
B29: Configuration of Cartridge Lid with Chamber Identification | K29: =IF(J29<>"",I29-J29,"") | L29: =IF(J29="","",IF($F$10="","",IF(K29<=$F$10,"PASS","FAIL"))) | M29: =IF(L29="PASS","NA","")
K31: =IF(J31<>"",I31-J31,"") | L31: =IF(J31="","",IF($F$10="","",IF(K31<=$F$10,"PASS","FAIL"))) | M31: =IF(L31="PASS","NA","")
K33: =IF(J33<>"",I33-J33,"") | L33: =IF(J33="","",IF($F$10="","",IF(K33<=$F$10,"PASS","FAIL"))) | M33: =IF(L33="PASS","NA","")
K35: =IF(J35<>"",I35-J35,"") | L35: =IF(J35="","",IF($F$10="","",IF(K35<=$F$10,"PASS","FAIL"))) | M35: =IF(L35="PASS","NA","")
K37: =IF(J37<>"",I37-J37,"") | L37: =IF(J37="","",IF($F$10="","",IF(K37<=$F$10,"PASS","FAIL"))) | M37: =IF(L37="PASS","NA","")
K39: =IF(J39<>"",I39-J39,"") | L39: =IF(J39="","",IF($F$10="","",IF(K39<=$F$10,"PASS","FAIL"))) | M39: =IF(L39="PASS","NA","")
K41: =IF(J41<>"",I41-J41,"") | L41: =IF(J41="","",IF($F$10="","",IF(K41<=$F$10,"PASS","FAIL"))) | M41: =IF(L41="PASS","NA","")
B42: Name of Tester
K43: =IF(J43<>"",I43-J43,"") | L43: =IF(J43="","",IF($F$10="","",IF(K43<=$F$10,"PASS","FAIL"))) | M43: =IF(L43="PASS","NA","")
K45: =IF(J45<>"",I45-J45,"") | L45: =IF(J45="","",IF($F$10="","",IF(K45<=$F$10,"PASS","FAIL"))) | M45: =IF(L45="PASS","NA","")
B46: Signature | D46: Date
B50: Comments | K50: For Information Only
K51: OC Mold(s) | M51: Lid Mold(s)

Sheet Replacement Cartridge (13)
B1: Part Number | D1: Batch Number(s) | F1: ROBAL | H1: Cartridge ID | I1: Initial Weight (mg) | J1: Final Weight (mg) | K1: Weight Loss (mg) | L1: Weight Loss Pass/Fail | M1: Observation
B2: =IF('Datasheet (1)'!B2:C3="","",'Datasheet (1)'!B2:C3) | D2: =IF('Datasheet (1)'!D2:E3="","",'Datasheet (1)'!D2:E3) | F2: =IF('Datasheet (1)'!F2:F3="","",'Datasheet (1)'!F2:F3)
K3: =IF(J3<>"",I3-J3,"") | L3: =IF(J3="","",IF($F$10="","",IF(K3<=$F$10,"PASS","FAIL"))) | M3: =IF(L3="PASS","NA","" )
B5: Cartridge Number (LSP) | D5: NOTE - All weight measurements should be done in "mg" and recorded in "mg". | K5: =IF(J5<>"",I5-J5,"") | L5: =IF(J5="","",IF($F$10="","",IF(K5<=$F$10,"PASS","FAIL"))) | M5: =IF(L5="PASS","NA","")
B6: =IF('Datasheet (1)'!B6:C7="","",'Datasheet (1)'!B6:C7)
K7: =IF(J7<>"",I7-J7,"") | L7: =IF(J7="","",IF($F$10="","",IF(K7<=$F$10,"PASS","FAIL"))) | M7: =IF(L7="PASS","NA","")
